<?xml version="1.0"?>
<robot xmlns:xacro="http://www.ros.org/wiki/xacro">
  <link
    name="link6">
    <inertial>
      <origin
        xyz="-1.73161952832235E-08 0.030376154976061 0.00157120108851105"
        rpy="0 0 0" />
      <mass
        value="0.047698791752954" />
      <inertia
        ixx="7.72284261455913E-06"
        ixy="3.00758647890756E-11"
        ixz="4.70631210623446E-13"
        iyy="1.33650599715037E-05"
        iyz="-3.83488938701045E-07"
        izz="1.25814742515456E-05" />
    </inertial>
    <visual>
      <origin
        xyz="0 0 0"
        rpy="0 0 0" />
      <geometry>
        <mesh
          filename="package://dummy_description/meshes/effector/EB-GP-01/link6.STL" />
      </geometry>
      <material
        name="">
        <color
          rgba="1 1 1 1" />
      </material>
    </visual>
    <collision>
      <origin
        xyz="0 0 0"
        rpy="0 0 0" />
      <geometry>
        <mesh
          filename="package://dummy_description/meshes/effector/EB-GP-01/link6.STL" />
      </geometry>
    </collision>
  </link>
  <link
    name="link7">
    <inertial>
      <origin
        xyz="0.00152612188957103 0.0176930965044017 0.00939698783663878"
        rpy="0 0 0" />
      <mass
        value="0.012637168125042" />
      <inertia
        ixx="3.96285079028416E-06"
        ixy="1.42866720295799E-07"
        ixz="-1.82056467439345E-09"
        iyy="1.0694147523531E-06"
        iyz="1.44746708205008E-08"
        izz="4.42805634971276E-06" />
    </inertial>
    <visual>
      <origin
        xyz="0 0 0"
        rpy="0 0 0" />
      <geometry>
        <mesh
          filename="package://dummy_description/meshes/effector/EB-GP-01/link7.STL" />
      </geometry>
      <material
        name="">
        <color
          rgba="0.9 0.9 0.9 1" />
      </material>
    </visual>
    <collision>
      <origin
        xyz="0 0 0"
        rpy="0 0 0" />
      <geometry>
        <mesh
          filename="package://dummy_description/meshes/effector/EB-GP-01/link7.STL" />
      </geometry>
    </collision>
  </link>
  <link name="gripper_base"/>

  <joint
    name="joint7"
    type="revolute">
    <origin
      xyz="0.028034 0.070463 0.01"
      rpy="3.14 0 -3.0526" />
    <parent
      link="link6" />
    <child
      link="gripper_base" />
    <axis
      xyz="0 0 -1" />
    <limit
      lower="-10"
      upper="10"
      effort="10"
      velocity="10" />
  </joint>

  <joint
    name="left_gripper_joint"
    type="revolute">
    <origin
      xyz="0.028034 0.070463 0.01"
      rpy="3.14 0 -3.0526" />
    <parent
      link="link6" />
    <child
      link="link7" />
    <axis
      xyz="0 0 -1" />
    <limit
      lower="-0.27"
      upper="0.27"
      effort="10"
      velocity="10" />
    <mimic
      joint="joint7"
      multiplier="0.03"
      offset="0"/>
  </joint>
  <link
    name="link8">
    <inertial>
      <origin
        xyz="0.00152612188957089 0.0176930965044017 -0.00810301216336123"
        rpy="0 0 0" />
      <mass
        value="0.012637168125042" />
      <inertia
        ixx="3.96285079028415E-06"
        ixy="1.42866720295798E-07"
        ixz="-1.82056467438641E-09"
        iyy="1.0694147523531E-06"
        iyz="1.44746708205124E-08"
        izz="4.42805634971275E-06" />
    </inertial>
    <visual>
      <origin
        xyz="0 0 0"
        rpy="0 0 0" />
      <geometry>
        <mesh
          filename="package://dummy_description/meshes/effector/EB-GP-01/link8.STL" />
      </geometry>
      <material
        name="">
        <color
          rgba="0.9 0.9 0.9 1" />
      </material>
    </visual>
    <collision>
      <origin
        xyz="0 0 0"
        rpy="0 0 0" />
      <geometry>
        <mesh
          filename="package://dummy_description/meshes/effector/EB-GP-01/link8.STL" />
      </geometry>
    </collision>
  </link>
  <joint
    name="right_gripper_joint"
    type="revolute">
    <origin
      xyz="-0.028034 0.070463 0.0085"
      rpy="0 0 -0.089018" />
    <parent
      link="link6" />
    <child
      link="link8" />
    <axis
      xyz="0 0 1" />
    <limit
      lower="-0.27"
      upper="0.27"
      effort="10"
      velocity="10" />
    <mimic
      joint="joint7"
      multiplier="-0.03"
      offset="0"/>
  </joint>

  <link name="tool0">
    <inertial>
      <origin xyz="0 0 0" rpy="0 0 0"/>
      <mass value="0.1"/>
      <inertia ixx="0.0001" ixy="0" ixz="0" iyy="0.0001" iyz="0" izz="0.0001"/>
    </inertial>
  </link>
  <joint name="tool_joint" type="fixed">
    <parent link="link6"/>
    <child link="tool0"/>
    <origin xyz="0 0 0" rpy="1.57 1.57 0"/>
  </joint>
</robot>